Workbook

Sheet 使い方
B2: 記帳設計シート(財務諸表の記帳方法の設計図)
B3: 会社の記帳ルールを、8つの領域・62項目で決めていくためのブックです。
B5: シートの構成
B6: 設計シート | C6: 62項目の設定を記入するメインのシート。選択肢がある項目は、セルを選ぶとリストから選べる
B7: 勘定科目表 | C7: 使う勘定科目の一覧のひな形。不要な科目は「使う」を×にし、自社の科目を追加する
B8: 決算整理チェック | C8: 決算整理事項ごとの仕訳の型と、担当・期限・完了を管理する
B9: 進捗 | C9: 領域ごとに、状態を「決定」にした項目の数を自動で集計する(数式なので記入不要)
B11: 記入のルール
B12: 黄色のセル | C12: 記入する欄。それ以外のセルは説明・数式なので、そのままにしておく
B13: 状態 | C13: 未着手 → 検討中 → 決定 の3つから選ぶ。「決定」にすると緑色になり、進捗に数えられる
B14: 記入例の列 | C14: 設計シートの「記入例」は、中小の卸売業を想定した一例。そのまま写さず、自社に合わせて決める
B15: 複数選ぶ項目 | C15: 選択肢が複数選べる項目(「複数可」と書いた項目)は、「・」で区切って入力する
B17: 設計の順番
B18: おすすめの順番 | C18: ① 前提条件 → ④ 会計方針 → ③ 勘定科目体系 → ② 帳簿組織 → ⑤ 日常取引の記帳ルール → ⑥ 月次・決算プロセス → ⑦ 財務諸表の表示ルール
B19: 理由 | C19: 会計方針を先に決めないと、必要な勘定科目が決まらない。例:売上原価対立法なら「商品」「売上原価」、三分法なら「仕入」「繰越商品」が必要
B20: ⑧ 統制・保存・税務 | C20: 全工程と並行して整える

Sheet 設計シート
A1: 記帳設計シート
A2: 会社名 | F2: 決定 | G2: =COUNTIF(H6:H75,"決定")&" / "&COUNTA(H6:H75)&" 項目" -> 0 / 62 項目
F3: 進捗率 | G3: =IFERROR(COUNTIF(H6:H75,"決定")/COUNTA(H6:H75),0) -> 0
A5: No | B5: 領域 | C5: 設定項目 | D5: 選択肢 | E5: 記入のヒント | F5: 自社の設定 | G5: 決めた理由・メモ | H5: 状態 | I5: 記入例 | J5: 仕訳の例
A6: ① 前提条件 ― すべての土台。ここが決まらないと他が決まらない
A7: 1-1 | B7: 前提条件 | C7: 適用する会計基準 | D7: 企業会計基準(日本基準) / 中小企業の会計に関する指針 / 中小企業の会計に関する基本要領 / IFRS(国際財務報告基準) | E7: 上場会社や会計監査人を置く会社は企業会計基準。中小企業は指針か要領を選ぶことが多い | H7: 未着手 | I7: 中小企業の会計に関する指針
A8: 1-2 | B8: 前提条件 | C8: 決算日(会計期間) | D8: (自由記入) | E8: 例:3月31日(4月1日〜翌3月31日) | H8: 未着手 | I8: 3月31日
A9: 1-3 | B9: 前提条件 | C9: 月次決算 | D9: 毎月行う / 四半期ごとに行う / 年1回の決算だけ | E9: 毎月行うと、試算表で業績を早く確認できる | H9: 未着手 | I9: 毎月行う
A10: 1-4 | B10: 前提条件 | C10: 記帳の単位 | D10: 会社全体で1本 / 本支店会計 / 部門別会計 | E10: 支店が独立して記帳するなら本支店会計。決算で本支店合併財務諸表を作る | H10: 未着手 | I10: 部門別会計
A11: 1-5 | B11: 前提条件 | C11: 消費税の経理方式 | D11: 税抜方式 / 税込方式 | E11: 税抜方式は消費税を仮払消費税・仮受消費税で分けて記録する。課税事業者は税抜方式が一般的 | H11: 未着手 | I11: 税抜方式 | J11: 【税抜方式】 商品1,000円(税100円)を掛けで仕入れた (借)仕入 1,000 ／ (貸)買掛金 1,100 (借)仮払消費税 100 決算:仮受消費税300・仮払消費税100を相殺 (借)仮受消費税 300 ／ (貸)仮払消費税 100 ／ (貸)未払消費税 200 【税込方式】 商品1,000円(税100円)を掛けで仕入れた (借)仕入 1,100 ／ (貸)買掛金 1,100 決算:納付額200を計上 (借)租税公課 200 ／ (貸)未払消費税 200
A12: 1-6 | B12: 前提条件 | C12: 消費税の計算方法 | D12: 本則課税(原則課税) / 簡易課税 / 免税事業者 | E12: 簡易課税は基準期間の課税売上高5,000万円以下で、届出をした場合に選べる | H12: 未着手 | I12: 本則課税(原則課税)
A13: 1-7 | B13: 前提条件 | C13: インボイス(適格請求書発行事業者) | D13: 登録している / 登録していない | E13: 仕入先が未登録の場合、仕入税額控除の経過措置の扱いも決めておく | H13: 未着手 | I13: 登録している
A14: 1-8 | B14: 前提条件 | C14: 通貨と端数処理 | D14: (自由記入) | E14: 例:円単位、1円未満は切り捨て | H14: 未着手 | I14: 円単位・1円未満切り捨て
A15: ② 帳簿組織 ― どの帳簿を置き、どうつなぐか
A16: 2-1 | B16: 帳簿組織 | C16: 仕訳の起票方法 | D16: 仕訳帳に直接記入 / 会計ソフトに直接入力 / 三伝票制(入金・出金・振替) / 五伝票制(+売上・仕入) | E16: 伝票制にすると、担当者ごとに分けて起票しやすい | H16: 未着手 | I16: 会計ソフトに直接入力 | J16: 【三伝票制(入金・出金・振替)】 入金伝票「売掛金 50,000」の意味 (借)現金 50,000 ／ (貸)売掛金 50,000 出金伝票「旅費交通費 3,000」の意味 (借)旅費交通費 3,000 ／ (貸)現金 3,000 【五伝票制(+売上・仕入)】 売上伝票「A社 80,000」の意味(すべて掛けとして起票) (借)売掛金 80,000 ／ (貸)売上 80,000
A17: 2-2 | B17: 帳簿組織 | C17: 一部現金取引の起票 | D17: 取引を分解して起票 / いったん全額掛けとして起票 | E17: 例:売上100,000のうち30,000を現金で受け取り、残りは掛け。伝票制を使うときに決める | H17: 未着手 | I17: いったん全額掛けとして起票 | J17: 【取引を分解して起票】 入金伝票 (借)現金 30,000 ／ (貸)売上 30,000 振替伝票 (借)売掛金 70,000 ／ (貸)売上 70,000 【いったん全額掛けとして起票】 振替伝票 (借)売掛金 100,000 ／ (貸)売上 100,000 入金伝票 (借)現金 30,000 ／ (貸)売掛金 30,000
A18: 2-3 | B18: 帳簿組織 | C18: 総勘定元帳への転記 | D18: 仕訳ごとに1件ずつ転記 / 仕訳日計表で毎日まとめて転記 / 仕訳週計表で毎週まとめて転記 | E18: 会計ソフトなら入力と同時に自動で転記される | H18: 未着手 | I18: 仕訳ごとに1件ずつ転記
A19: 2-4 | B19: 帳簿組織 | C19: 使う補助記入帳 | D19: (複数可)現金出納帳・当座預金出納帳・小口現金出納帳・売上帳・仕入帳・受取手形記入帳・支払手形記入帳 | E19: 取引の明細を日付順に記録する帳簿 | H19: 未着手 | I19: 現金出納帳・当座預金出納帳・売上帳・仕入帳
A20: 2-5 | B20: 帳簿組織 | C20: 使う補助元帳 | D20: (複数可)売掛金元帳(得意先元帳)・買掛金元帳(仕入先元帳)・商品有高帳・固定資産台帳 | E20: 勘定の内訳を、相手先別・品目別に記録する帳簿 | H20: 未着手 | I20: 売掛金元帳(得意先元帳)・買掛金元帳(仕入先元帳)・固定資産台帳
A21: 2-6 | B21: 帳簿組織 | C21: 使う会計ソフト・システム | D21: (自由記入) | E21: 例:クラウド会計ソフト、販売管理システムと連携 | H21: 未着手 | I21: クラウド会計ソフト(銀行明細を自動取込)
A22: ③ 勘定科目体系 ― 会社の“科目の辞書”を作る
A23: 3-1 | B23: 勘定科目体系 | C23: 科目コードのルール | D23: (自由記入) | E23: 例:4桁で、先頭1=資産、2=負債、3=純資産、4=収益、5〜=費用 | H23: 未着手 | I23: 4桁(1xxx資産・2xxx負債・3xxx純資産・4xxx収益・5xxx以降費用)
A24: 3-2 | B24: 勘定科目体系 | C24: 預金の補助科目 | D24: 口座ごとに設定する / 設定しない | E24: 口座ごとに分けると、銀行残高との照合がしやすい | H24: 未着手 | I24: 口座ごとに設定する
A25: 3-3 | B25: 勘定科目体系 | C25: 売掛金・買掛金の内訳管理 | D25: 取引先ごとに補助科目を設定 / 補助元帳だけで管理 / 管理しない | E25: 総勘定元帳の売掛金(統制勘定)と、取引先別の合計が一致するようにする | H25: 未着手 | I25: 取引先ごとに補助科目を設定
A26: 3-4 | B26: 勘定科目体系 | C26: 部門・プロジェクトの管理 | D26: 部門タグを使う / 部門とプロジェクトのタグを使う / 使わない | E26: 管理会計(部門別の損益)を見るかどうかで決める | H26: 未着手 | I26: 部門タグを使う
A27: 3-5 | B27: 勘定科目体系 | C27: 費用科目の細かさ | D27: (自由記入) | E27: 例:消耗品費と事務用品費を分けるか。分けすぎると入力ミスが増える | H27: 未着手 | I27: 少額の備品・文具はまとめて消耗品費
A28: 3-6 | B28: 勘定科目体系 | C28: 表示科目へのまとめ方 | D28: (自由記入) | E28: 帳簿の科目を財務諸表の表示科目にまとめるルール | H28: 未着手 | I28: 現金・当座預金・普通預金 → 現金及び預金
A29: ④ 会計方針 ― 財務諸表の数字そのものが変わる最重要部分
A30: 4-1 | B30: 会計方針 | C30: 収益を計上するタイミング | D30: 出荷基準 / 着荷基準 / 検収基準 | E30: 収益認識基準では、支配が顧客に移った時点で計上する。国内販売なら出荷基準も認められる場合がある | H30: 未着手 | I30: 出荷基準 | J30: 仕訳の形は同じで、計上する日が変わる (借)売掛金 150,000 ／ (貸)売上 150,000
A31: 4-2 | B31: 会計方針 | C31: 商品売買の記帳法 | D31: 三分法 / 売上原価対立法 / 分記法 | E31: 原価1,000円の商品を1,500円で掛け売りした場合で比べる | H31: 未着手 | I31: 三分法 | J31: 【三分法】 販売時 (借)売掛金 1,500 ／ (貸)売上 1,500 決算:期首商品200・期末商品300 (借)仕入 200 ／ (貸)繰越商品 200 (借)繰越商品 300 ／ (貸)仕入 300 【売上原価対立法】 販売時に原価も計上する (借)売掛金 1,500 ／ (貸)売上 1,500 (借)売上原価 1,000 ／ (貸)商品 1,000 【分記法】 販売時に利益を分けて計上する (借)売掛金 1,500 ／ (貸)商品 1,000 ／ (貸)商品売買益 500
A32: 4-3 | B32: 会計方針 | C32: 払出単価の計算方法 | D32: 先入先出法 / 移動平均法 / 総平均法 | E32: 商品有高帳の付け方と売上原価の金額が変わる | H32: 未着手 | I32: 移動平均法
A33: 4-4 | B33: 会計方針 | C33: 棚卸資産の簿価切下げ | D33: 洗替法 / 切放法 | E33: 正味売却価額が帳簿価額を下回ったら切り下げる。洗替法は翌期首に戻し入れる | H33: 未着手 | I33: 洗替法 | J33: 【洗替法】 決算:評価損20を計上 (借)商品評価損 20 ／ (貸)繰越商品 20 翌期首:戻し入れ (借)繰越商品 20 ／ (貸)商品評価損戻入益 20 【切放法】 決算:評価損20を計上(翌期は戻さない) (借)商品評価損 20 ／ (貸)繰越商品 20
A34: 4-5 | B34: 会計方針 | C34: 減価償却の方法 | D34: 定額法 / 定率法(200%定率法) / 生産高比例法 | E34: 例:取得原価1,000,000円・耐用年数5年・残存価額0の備品の1年目 | H34: 未着手 | I34: 定額法 | J34: 【定額法】 1,000,000 ÷ 5年 = 200,000 (借)減価償却費 200,000 ／ (貸)備品減価償却累計額 200,000 【定率法(200%定率法)】 償却率 1÷5年×200% = 0.400、1,000,000 × 0.400 = 400,000 (借)減価償却費 400,000 ／ (貸)備品減価償却累計額 400,000 【生産高比例法】 総見積生産量10,000個のうち当期2,500個 → 1,000,000 × 2,500/10,000 = 250,000 (借)減価償却費 250,000 ／ (貸)機械装置減価償却累計額 250,000
A35: 4-6 | B35: 会計方針 | C35: 減価償却の記帳方法 | D35: 間接法 / 直接法 | E35: 間接法なら、取得原価と累計額を両方残せる | H35: 未着手 | I35: 間接法 | J35: 【間接法】 (借)減価償却費 100 ／ (貸)備品減価償却累計額 100 【直接法】 (借)減価償却費 100 ／ (貸)備品 100
A36: 4-7 | B36: 会計方針 | C36: 固定資産に計上する基準 | D36: (自由記入) | E36: 例:取得価額10万円以上は資産に計上し、未満は消耗品費 | H36: 未着手 | I36: 取得価額10万円以上を資産計上
A37: 4-8 | B37: 会計方針 | C37: 貸倒引当金の繰入方法 | D37: 差額補充法 / 洗替法 | E37: 例:設定額300、決算前の引当金残高100 | H37: 未着手 | I37: 差額補充法 | J37: 【差額補充法】 不足する200だけ繰り入れる (借)貸倒引当金繰入 200 ／ (貸)貸倒引当金 200 【洗替法】 残高100を戻し入れ、300を改めて繰り入れる (借)貸倒引当金 100 ／ (貸)貸倒引当金戻入 100 (借)貸倒引当金繰入 300 ／ (貸)貸倒引当金 300
A38: 4-9 | B38: 会計方針 | C38: 貸倒見積高の算定 | D38: (自由記入) | E38: 一般債権は貸倒実績率法、貸倒懸念債権は財務内容評価法など、債権の区分ごとに決める | H38: 未着手 | I38: 一般債権:過去3年の貸倒実績率
A39: 4-10 | B39: 会計方針 | C39: その他に計上する引当金 | D39: (複数可)賞与引当金・退職給付引当金・修繕引当金・製品保証引当金 | E39: 将来の費用で、発生の可能性が高く金額を見積もれるものを計上する | H39: 未着手 | I39: 賞与引当金
A40: 4-11 | B40: 会計方針 | C40: その他有価証券の評価差額 | D40: 全部純資産直入法 / 部分純資産直入法 | E40: 違いが出るのは評価差損のとき。例:取得原価1,000、期末時価900 | H40: 未着手 | I40: 全部純資産直入法 | J40: 【全部純資産直入法】 評価差損も純資産に直接計上(税効果は省略) (借)その他有価証券評価差額金 100 ／ (貸)その他有価証券 100 【部分純資産直入法】 評価差損は当期の損失に計上(税効果は省略) (借)投資有価証券評価損 100 ／ (貸)その他有価証券 100
A41: 4-12 | B41: 会計方針 | C41: 外貨建取引の換算レート | D41: (自由記入) | E41: 取引日の直物レートが原則。前月末レートなど合理的なレートを使うこともある | H41: 未着手 | I41: 取引日の直物レート(TTM)
...

Sheet 勘定科目表
A1: 勘定科目表(ひな形)
A2: 黄色の「使う」を ○/× で選ぶ。自社で使う科目は空いている行に追加する。コードは「1xxx資産・2xxx負債・3xxx純資産・4xxx収益・5xxx以降費用」の例
G3: =COUNTIF(G5:G87,"○")&" 科目を使用" -> 68 科目を使用
A4: コード | B4: 勘定科目 | C4: 5要素 | D4: 表示区分 | E4: 財務諸表の表示科目 | F4: 補助科目(例) | G4: 使う | H4: メモ
A5: 1110 | B5: 現金 | C5: 資産 | D5: 流動資産 | E5: 現金及び預金 | G5: ○
A6: 1120 | B6: 小口現金 | C6: 資産 | D6: 流動資産 | E6: 現金及び預金 | G6: ○
A7: 1130 | B7: 当座預金 | C7: 資産 | D7: 流動資産 | E7: 現金及び預金 | F7: 口座ごと | G7: ○
A8: 1140 | B8: 普通預金 | C8: 資産 | D8: 流動資産 | E8: 現金及び預金 | F8: 口座ごと | G8: ○
A9: 1210 | B9: 受取手形 | C9: 資産 | D9: 流動資産 | E9: 受取手形 | F9: 取引先ごと | G9: ○
A10: 1220 | B10: 電子記録債権 | C10: 資産 | D10: 流動資産 | E10: 電子記録債権 | F10: 取引先ごと | G10: ○
A11: 1230 | B11: 売掛金 | C11: 資産 | D11: 流動資産 | E11: 売掛金 | F11: 取引先ごと | G11: ○
A12: 1240 | B12: クレジット売掛金 | C12: 資産 | D12: 流動資産 | E12: 売掛金 | F12: カード会社ごと | G12: ○
A13: 1250 | B13: 貸倒引当金 | C13: 資産(評価勘定) | D13: 流動資産 | E13: 貸倒引当金(控除) | G13: ○
A14: 1310 | B14: 有価証券 | C14: 資産 | D14: 流動資産 | E14: 有価証券 | F14: 銘柄ごと | G14: ○
A15: 1410 | B15: 商品(繰越商品) | C15: 資産 | D15: 流動資産 | E15: 商品 | G15: ○
A16: 1510 | B16: 前払費用 | C16: 資産 | D16: 流動資産 | E16: 前払費用 | G16: ○
A17: 1520 | B17: 未収収益 | C17: 資産 | D17: 流動資産 | E17: 未収収益 | G17: ○
A18: 1530 | B18: 仮払金 | C18: 資産 | D18: 流動資産 | E18: その他 | G18: ○
A19: 1540 | B19: 仮払消費税 | C19: 資産 | D19: 流動資産 | E19: (決算で相殺) | G19: ○
A20: 1550 | B20: 仮払法人税等 | C20: 資産 | D20: 流動資産 | E20: (決算で精算) | G20: ○
A21: 1610 | B21: 建物 | C21: 資産 | D21: 有形固定資産 | E21: 建物 | G21: ○
A22: 1611 | B22: 建物減価償却累計額 | C22: 資産(評価勘定) | D22: 有形固定資産 | E22: 減価償却累計額(控除) | G22: ○
A23: 1620 | B23: 備品 | C23: 資産 | D23: 有形固定資産 | E23: 工具、器具及び備品 | G23: ○
A24: 1621 | B24: 備品減価償却累計額 | C24: 資産(評価勘定) | D24: 有形固定資産 | E24: 減価償却累計額(控除) | G24: ○
A25: 1630 | B25: 車両運搬具 | C25: 資産 | D25: 有形固定資産 | E25: 車両運搬具 | G25: ○
A26: 1640 | B26: 土地 | C26: 資産 | D26: 有形固定資産 | E26: 土地 | G26: ○
A27: 1710 | B27: ソフトウェア | C27: 資産 | D27: 無形固定資産 | E27: ソフトウェア | G27: ○
A28: 1810 | B28: 投資有価証券 | C28: 資産 | D28: 投資その他の資産 | E28: 投資有価証券 | F28: 銘柄ごと | G28: ○
A29: 1820 | B29: 繰延税金資産 | C29: 資産 | D29: 投資その他の資産 | E29: 繰延税金資産 | G29: ○
A30: 2110 | B30: 支払手形 | C30: 負債 | D30: 流動負債 | E30: 支払手形 | F30: 取引先ごと | G30: ○
A31: 2120 | B31: 電子記録債務 | C31: 負債 | D31: 流動負債 | E31: 電子記録債務 | F31: 取引先ごと | G31: ○
A32: 2130 | B32: 買掛金 | C32: 負債 | D32: 流動負債 | E32: 買掛金 | F32: 取引先ごと | G32: ○
A33: 2140 | B33: 短期借入金 | C33: 負債 | D33: 流動負債 | E33: 短期借入金 | F33: 借入先ごと | G33: ○
A34: 2150 | B34: 未払金 | C34: 負債 | D34: 流動負債 | E34: 未払金 | G34: ○
A35: 2160 | B35: 未払費用 | C35: 負債 | D35: 流動負債 | E35: 未払費用 | G35: ○
A36: 2170 | B36: 未払法人税等 | C36: 負債 | D36: 流動負債 | E36: 未払法人税等 | G36: ○
A37: 2180 | B37: 未払消費税 | C37: 負債 | D37: 流動負債 | E37: 未払消費税等 | G37: ○
A38: 2190 | B38: 仮受消費税 | C38: 負債 | D38: 流動負債 | E38: (決算で相殺) | G38: ○
A39: 2210 | B39: 前受金 | C39: 負債 | D39: 流動負債 | E39: 前受金 | G39: ○
A40: 2220 | B40: 預り金 | C40: 負債 | D40: 流動負債 | E40: 預り金 | F40: 所得税・住民税・社会保険料 | G40: ○
...

Sheet 決算整理チェック
A1: 決算整理チェックリスト
A2: 毎回の決算で使う。黄色の欄(担当・期限・完了・メモ)を記入する。仕訳の金額は例 | G2: =COUNTIF(G5:G17,"済")&" / "&COUNTA(B5:B17)&" 完了" -> 0 / 13 完了
A4: No | B4: 決算整理事項 | C4: 仕訳の型(例) | D4: 根拠資料 | E4: 担当 | F4: 期限 | G4: 完了 | H4: メモ
A5: 1 | B5: 売上原価の計算(三分法) | C5: (借)仕入 200 ／(貸)繰越商品 200 (借)繰越商品 300 ／(貸)仕入 300 | D5: 商品有高帳・棚卸表 | G5: 未
A6: 2 | B6: 棚卸減耗損・商品評価損 | C6: (借)棚卸減耗損 50 ／(貸)繰越商品 50 (借)商品評価損 20 ／(貸)繰越商品 20 | D6: 実地棚卸表 | G6: 未
A7: 3 | B7: 減価償却 | C7: (借)減価償却費 200,000 ／(貸)備品減価償却累計額 200,000 | D7: 固定資産台帳 | G7: 未
A8: 4 | B8: 貸倒引当金(差額補充法) | C8: (借)貸倒引当金繰入 200 ／(貸)貸倒引当金 200 | D8: 売掛金元帳・貸倒実績率 | G8: 未
A9: 5 | B9: 経過勘定(前払・未払・未収・前受) | C9: (借)支払家賃 10,000 ／(貸)未払家賃 10,000 | D9: 契約書 | G9: 未
A10: 6 | B10: 有価証券の評価 | C10: (借)その他有価証券 100 ／(貸)その他有価証券評価差額金 100 | D10: 時価の資料 | G10: 未
A11: 7 | B11: 外貨建項目の換算 | C11: (借)売掛金 1,000 ／(貸)為替差損益 1,000 | D11: 決算日レート | G11: 未
A12: 8 | B12: 賞与・退職給付などの引当金 | C12: (借)賞与引当金繰入 500,000 ／(貸)賞与引当金 500,000 | D12: 支給見込額 | G12: 未
A13: 9 | B13: 現金過不足の整理 | C13: (借)雑損 500 ／(貸)現金過不足 500 | D13: 現金出納帳 | G13: 未
A14: 10 | B14: 消費税の整理(税抜方式) | C14: (借)仮受消費税 300 ／(貸)仮払消費税 100 ／(貸)未払消費税 200 | D14: 消費税の計算書 | G14: 未
A15: 11 | B15: 法人税等 | C15: (借)法人税、住民税及び事業税 500,000 ／(貸)仮払法人税等 200,000 ／(貸)未払法人税等 300,000 | D15: 税額計算書 | G15: 未
A16: 12 | B16: 税効果会計 | C16: (借)繰延税金資産 300 ／(貸)法人税等調整額 300 | D16: 一時差異の一覧 | G16: 未
A17: 13 | B17: 帳簿の締切・繰越 | C17: 収益・費用を損益勘定へ、当期純利益を繰越利益剰余金へ振替 | D17: 総勘定元帳 | G17: 未

Sheet 進捗
A1: 領域ごとの進捗(自動集計)
A2: 設計シートの「状態」から自動で計算する。記入は不要
A4: 領域 | B4: 項目数 | C4: 決定 | D4: 検討中 | E4: 未着手 | F4: 進捗率
A5: ① 前提条件 | B5: =COUNTIF(設計シート!$B$6:$B$75,"前提条件") -> 8 | C5: =COUNTIFS(設計シート!$B$6:$B$75,"前提条件",設計シート!$H$6:$H$75,"決定") -> 0 | D5: =COUNTIFS(設計シート!$B$6:$B$75,"前提条件",設計シート!$H$6:$H$75,"検討中") -> 0 | E5: =COUNTIFS(設計シート!$B$6:$B$75,"前提条件",設計シート!$H$6:$H$75,"未着手") -> 8 | F5: =IFERROR(C5/B5,0) -> 0
A6: ② 帳簿組織 | B6: =COUNTIF(設計シート!$B$6:$B$75,"帳簿組織") -> 6 | C6: =COUNTIFS(設計シート!$B$6:$B$75,"帳簿組織",設計シート!$H$6:$H$75,"決定") -> 0 | D6: =COUNTIFS(設計シート!$B$6:$B$75,"帳簿組織",設計シート!$H$6:$H$75,"検討中") -> 0 | E6: =COUNTIFS(設計シート!$B$6:$B$75,"帳簿組織",設計シート!$H$6:$H$75,"未着手") -> 6 | F6: =IFERROR(C6/B6,0) -> 0
A7: ③ 勘定科目体系 | B7: =COUNTIF(設計シート!$B$6:$B$75,"勘定科目体系") -> 6 | C7: =COUNTIFS(設計シート!$B$6:$B$75,"勘定科目体系",設計シート!$H$6:$H$75,"決定") -> 0 | D7: =COUNTIFS(設計シート!$B$6:$B$75,"勘定科目体系",設計シート!$H$6:$H$75,"検討中") -> 0 | E7: =COUNTIFS(設計シート!$B$6:$B$75,"勘定科目体系",設計シート!$H$6:$H$75,"未着手") -> 6 | F7: =IFERROR(C7/B7,0) -> 0
A8: ④ 会計方針 | B8: =COUNTIF(設計シート!$B$6:$B$75,"会計方針") -> 13 | C8: =COUNTIFS(設計シート!$B$6:$B$75,"会計方針",設計シート!$H$6:$H$75,"決定") -> 0 | D8: =COUNTIFS(設計シート!$B$6:$B$75,"会計方針",設計シート!$H$6:$H$75,"検討中") -> 0 | E8: =COUNTIFS(設計シート!$B$6:$B$75,"会計方針",設計シート!$H$6:$H$75,"未着手") -> 13 | F8: =IFERROR(C8/B8,0) -> 0
A9: ⑤ 日常取引の記帳ルール | B9: =COUNTIF(設計シート!$B$6:$B$75,"日常取引の記帳ルール") -> 9 | C9: =COUNTIFS(設計シート!$B$6:$B$75,"日常取引の記帳ルール",設計シート!$H$6:$H$75,"決定") -> 0 | D9: =COUNTIFS(設計シート!$B$6:$B$75,"日常取引の記帳ルール",設計シート!$H$6:$H$75,"検討中") -> 0 | E9: =COUNTIFS(設計シート!$B$6:$B$75,"日常取引の記帳ルール",設計シート!$H$6:$H$75,"未着手") -> 9 | F9: =IFERROR(C9/B9,0) -> 0
A10: ⑥ 月次・決算プロセス | B10: =COUNTIF(設計シート!$B$6:$B$75,"月次・決算プロセス") -> 7 | C10: =COUNTIFS(設計シート!$B$6:$B$75,"月次・決算プロセス",設計シート!$H$6:$H$75,"決定") -> 0 | D10: =COUNTIFS(設計シート!$B$6:$B$75,"月次・決算プロセス",設計シート!$H$6:$H$75,"検討中") -> 0 | E10: =COUNTIFS(設計シート!$B$6:$B$75,"月次・決算プロセス",設計シート!$H$6:$H$75,"未着手") -> 7 | F10: =IFERROR(C10/B10,0) -> 0
A11: ⑦ 財務諸表の表示ルール | B11: =COUNTIF(設計シート!$B$6:$B$75,"財務諸表の表示ルール") -> 7 | C11: =COUNTIFS(設計シート!$B$6:$B$75,"財務諸表の表示ルール",設計シート!$H$6:$H$75,"決定") -> 0 | D11: =COUNTIFS(設計シート!$B$6:$B$75,"財務諸表の表示ルール",設計シート!$H$6:$H$75,"検討中") -> 0 | E11: =COUNTIFS(設計シート!$B$6:$B$75,"財務諸表の表示ルール",設計シート!$H$6:$H$75,"未着手") -> 7 | F11: =IFERROR(C11/B11,0) -> 0
A12: ⑧ 統制・保存・税務 | B12: =COUNTIF(設計シート!$B$6:$B$75,"統制・保存・税務") -> 6 | C12: =COUNTIFS(設計シート!$B$6:$B$75,"統制・保存・税務",設計シート!$H$6:$H$75,"決定") -> 0 | D12: =COUNTIFS(設計シート!$B$6:$B$75,"統制・保存・税務",設計シート!$H$6:$H$75,"検討中") -> 0 | E12: =COUNTIFS(設計シート!$B$6:$B$75,"統制・保存・税務",設計シート!$H$6:$H$75,"未着手") -> 6 | F12: =IFERROR(C12/B12,0) -> 0
A13: 合計 | B13: =SUM(B5:B12) -> 62 | C13: =SUM(C5:C12) -> 0 | D13: =SUM(D5:D12) -> 0 | E13: =SUM(E5:E12) -> 62 | F13: =IFERROR(C13/B13,0) -> 0
